Workbook

Sheet TABLEAU DE BORD
B1: TABLEAU DE BORD · PLANNING LOGISSIMO 2026
B4: ▼ SÉLECTION AGENT | E4: TOUS | K4: ℹ Utilisez la liste déroulante pour filtrer · Les données se mettent à jour automatiquement (A ne pas toucher)
AB5: TOUS | AC5: BARNEIX J. | AD5: 10
B6: 📊 ABSENCES PAR TYPE ET PAR MOIS | Q6: 👤 DÉTAIL PAR TYPE ET PAR AGENT | AB6: BARNEIX J. | AC6: MAJET P. | AD6: 9
B7: Type | C7: Jan | D7: Fév | E7: Mar | F7: Avr | G7: Mai | H7: Jun | I7: Jul | J7: Aoû | K7: Sep | L7: Oct | M7: Nov | N7: Déc | O7: TOTAL | Q7: Agent | R7: TP | S7: CSE/RPX | T7: CA/RC | U7: ATM/ATA | V7: ASA | W7: FORM | X7: Autre | Y7: TOTAL | AB7: MAJET P. | AC7: LENEVEU N. | AD7: 8
B8: TP | C8: =IF($E$4="TOUS",COUNTIF('01-26'!G10:AO10,"TP")+COUNTIF('01-26'!G9:AO9,"TP")+COUNTIF('01-26'!G8:AO8,"TP")+COUNTIF('01-26'!G11:AO11,"TP")+COUNTIF('01-26'!G12:AO12,"TP")+COUNTIF('01-26'!G13:AO13,"TP")+COUNTIF('01-26'!F14:AO14,"TP")+COUNTIF('01-26'!G15:AO15,"TP")+COUNTIF('01-26'!F16:AO16,"TP")+COUNTIF('01-26'!F17:AO17,"TP")+COUNTIF('01-26'!G18:AO18,"TP")+COUNTIF('01-26'!G19:AO19,"TP")+COUNTIF('01-26'!F20:AO20,"TP")+COUNTIF('01-26'!F21:AO21,"TP")+COUNTIF('01-26'!G22:AO22,"TP")+COUNTIF('01-26'!G23:AO23,"TP")+COUNTIF('01-26'!G24:AO24,"TP")+COUNTIF('01-26'!G25:AO25,"TP")+COUNTIF('01-26'!G26:AO26,"TP")+COUNTIF('01-26'!G27:AO27,"TP")+COUNTIF('01-26'!G28:AO28,"TP"),COUNTIF(INDIRECT("'01-26'!G"&VLOOKUP($E$4,$AC$5:$AD$25,2,FALSE())&":AO"&VLOOKUP($E$4,$AC$5:$AD$25,2,FALSE())),"TP")) -> 15 | D8: =IF($E$4="TOUS",COUNTIF('02-26'!G10:AO10,"TP")+COUNTIF('02-26'!G9:AO9,"TP")+COUNTIF('02-26'!G8:AO8,"TP")+COUNTIF('02-26'!G11:AO11,"TP")+COUNTIF('02-26'!F12:AO12,"TP")+COUNTIF('02-26'!G13:AO13,"TP")+COUNTIF('02-26'!G14:AO14,"TP")+COUNTIF('02-26'!F15:AO15,"TP")+COUNTIF('02-26'!G16:AO16,"TP")+COUNTIF('02-26'!F17:AO17,"TP")+COUNTIF('02-26'!G18:AO18,"TP")+COUNTIF('02-26'!G19:AO19,"TP")+COUNTIF('02-26'!F20:AO20,"TP")+COUNTIF('02-26'!G21:AO21,"TP")+COUNTIF('02-26'!G22:AO22,"TP")+COUNTIF('02-26'!G23:AO23,"TP")+COUNTIF('02-26'!G24:AO24,"TP")+COUNTIF('02-26'!G25:AO25,"TP")+COUNTIF('02-26'!G26:AO26,"TP")+COUNTIF('02-26'!G27:AO27,"TP")+COUNTIF('02-26'!G28:AO28,"TP"),COUNTIF(INDIRECT("'02-26'!G"&VLOOKUP($E$4,$AC$5:$AD$25,2,FALSE())&":AO"&VLOOKUP($E$4,$AC$5:$AD$25,2,FALSE())),"TP")) -> 15 | E8: =IF($E$4="TOUS",COUNTIF('03-26'!G10:AO10,"TP")+COUNTIF('03-26'!G9:AO9,"TP")+COUNTIF('03-26'!G8:AO8,"TP")+COUNTIF('03-26'!G11:AO11,"TP")+COUNTIF('03-26'!F12:AO12,"TP")+COUNTIF('03-26'!G13:AO13,"TP")+COUNTIF('03-26'!G14:AO14,"TP")+COUNTIF('03-26'!F15:AO15,"TP")+COUNTIF('03-26'!F16:AO16,"TP")+COUNTIF('03-26'!F17:AO17,"TP")+COUNTIF('03-26'!F18:AO18,"TP")+COUNTIF('03-26'!G19:AO19,"TP")+COUNTIF('03-26'!G20:AO20,"TP")+COUNTIF('03-26'!G21:AO21,"TP")+COUNTIF('03-26'!F22:AO22,"TP")+COUNTIF('03-26'!G23:AO23,"TP")+COUNTIF('03-26'!G24:AO24,"TP")+COUNTIF('03-26'!G25:AO25,"TP")+COUNTIF('03-26'!G26:AO26,"TP")+COUNTIF('03-26'!G27:AO27,"TP")+COUNTIF('03-26'!G28:AO28,"TP"),COUNTIF(INDIRECT("'03-26'!G"&VLOOKUP($E$4,$AC$5:$AD$25,2,FALSE())&":AO"&VLOOKUP($E$4,$AC$5:$AD$25,2,FALSE())),"TP")) -> 22 | F8: =IF($E$4="TOUS",COUNTIF('04-26'!G10:AO10,"TP")+COUNTIF('04-26'!G9:AO9,"TP")+COUNTIF('04-26'!G8:AO8,"TP")+COUNTIF('04-26'!G11:AO11,"TP")+COUNTIF('04-26'!F12:AO12,"TP")+COUNTIF('04-26'!G13:AO13,"TP")+COUNTIF('04-26'!F14:AO14,"TP")+COUNTIF('04-26'!G15:AO15,"TP")+COUNTIF('04-26'!G16:AO16,"TP")+COUNTIF('04-26'!G17:AO17,"TP")+COUNTIF('04-26'!G18:AO18,"TP")+COUNTIF('04-26'!G19:AO19,"TP")+COUNTIF('04-26'!G20:AO20,"TP")+COUNTIF('04-26'!G21:AO21,"TP")+COUNTIF('04-26'!G22:AO22,"TP")+COUNTIF('04-26'!G23:AO23,"TP")+COUNTIF('04-26'!G24:AO24,"TP")+COUNTIF('04-26'!G25:AO25,"TP")+COUNTIF('04-26'!G26:AO26,"TP")+COUNTIF('04-26'!G27:AO27,"TP")+COUNTIF('04-26'!G28:AO28,"TP"),COUNTIF(INDIRECT("'04-26'!G"&VLOOKUP($E$4,$AC$5:$AD$25,2,FALSE())&":AO"&VLOOKUP($E$4,$AC$5:$AD$25,2,FALSE())),"TP")) -> 10 | G8: =IF($E$4="TOUS",COUNTIF('05-26'!G10:AO10,"TP")+COUNTIF('05-26'!G9:AO9,"TP")+COUNTIF('05-26'!G8:AO8,"TP")+COUNTIF('05-26'!G11:AO11,"TP")+COUNTIF('05-26'!F12:AO12,"TP")+COUNTIF('05-26'!G13:AO13,"TP")+COUNTIF('05-26'!F14:AO14,"TP")+COUNTIF('05-26'!F15:AO15,"TP")+COUNTIF('05-26'!G16:AO16,"TP")+COUNTIF('05-26'!F17:AO17,"TP")+COUNTIF('05-26'!G18:AO18,"TP")+COUNTIF('05-26'!G19:AO19,"TP")+COUNTIF('05-26'!G20:AO20,"TP")+COUNTIF('05-26'!F21:AO21,"TP")+COUNTIF('05-26'!F22:AO22,"TP")+COUNTIF('05-26'!G23:AO23,"TP")+COUNTIF('05-26'!G24:AO24,"TP")+COUNTIF('05-26'!G25:AO25,"TP")+COUNTIF('05-26'!G26:AO26,"TP")+COUNTIF('05-26'!G27:AO27,"TP")+COUNTIF('05-26'!G28:AO28,"TP"),COUNTIF(INDIRECT("'05-26'!G"&VLOOKUP($E$4,$AC$5:$AD$25,2,FALSE())&":AO"&VLOOKUP($E$4,$AC$5:$AD$25,2,FALSE())),"TP")) -> 8 | H8: =IF($E$4="TOUS",COUNTIF('06-26'!G10:AO10,"TP")+COUNTIF('06-26'!G9:AO9,"TP")+COUNTIF('06-26'!G8:AO8,"TP")+COUNTIF('06-26'!G11:AO11,"TP")+COUNTIF('06-26'!F12:AO12,"TP")+COUNTIF('06-26'!G13:AO13,"TP")+COUNTIF('06-26'!F14:AO14,"TP")+COUNTIF('06-26'!F15:AO15,"TP")+COUNTIF('06-26'!F16:AO16,"TP")+COUNTIF('06-26'!F17:AO17,"TP")+COUNTIF('06-26'!G18:AO18,"TP")+COUNTIF('06-26'!G19:AO19,"TP")+COUNTIF('06-26'!G20:AO20,"TP")+COUNTIF('06-26'!F21:AO21,"TP")+COUNTIF('06-26'!F22:AO22,"TP")+COUNTIF('06-26'!G23:AO23,"TP")+COUNTIF('06-26'!G24:AO24,"TP")+COUNTIF('06-26'!G25:AO25,"TP")+COUNTIF('06-26'!G26:AO26,"TP")+COUNTIF('06-26'!G27:AO27,"TP")+COUNTIF('06-26'!G28:AO28,"TP"),COUNTIF(INDIRECT("'06-26'!G"&VLOOKUP($E$4,$AC$5:$AD$25,2,FALSE())&":AO"&VLOOKUP($E$4,$AC$5:$AD$25,2,FALSE())),"TP")) -> 20 | I8: =IF($E$4="TOUS",COUNTIF('07-26'!G10:AO10,"TP")+COUNTIF('07-26'!G9:AO9,"TP")+COUNTIF('07-26'!G8:AO8,"TP")+COUNTIF('07-26'!F11:AO11,"TP")+COUNTIF('07-26'!G12:AO12,"TP")+COUNTIF('07-26'!G13:AO13,"TP")+COUNTIF('07-26'!F14:AO14,"TP")+COUNTIF('07-26'!F15:AO15,"TP")+COUNTIF('07-26'!G16:AO16,"TP")+COUNTIF('07-26'!G17:AO17,"TP")+COUNTIF('07-26'!G18:AO18,"TP")+COUNTIF('07-26'!G19:AO19,"TP")+COUNTIF('07-26'!F20:AO20,"TP")+COUNTIF('07-26'!F21:AO21,"TP")+COUNTIF('07-26'!F22:AO22,"TP")+COUNTIF('07-26'!G23:AO23,"TP")+COUNTIF('07-26'!G24:AO24,"TP")+COUNTIF('07-26'!G25:AO25,"TP")+COUNTIF('07-26'!G26:AO26,"TP")+COUNTIF('07-26'!G27:AO27,"TP")+COUNTIF('07-26'!G28:AO28,"TP"),COUNTIF(INDIRECT("'07-26'!G"&VLOOKUP($E$4,$AC$5:$AD$25,2,FALSE())&":AO"&VLOOKUP($E$4,$AC$5:$AD$25,2,FALSE())),"TP")) -> 5 | J8: =IF($E$4="TOUS",COUNTIF('08-26'!G10:AO10,"TP")+COUNTIF('08-26'!G9:AO9,"TP")+COUNTIF('08-26'!G8:AO8,"TP")+COUNTIF('08-26'!F11:AO11,"TP")+COUNTIF('08-26'!F12:AO12,"TP")+COUNTIF('08-26'!F13:AO13,"TP")+COUNTIF('08-26'!F14:AO14,"TP")+COUNTIF('08-26'!F15:AO15,"TP")+COUNTIF('08-26'!G16:AO16,"TP")+COUNTIF('08-26'!F17:AO17,"TP")+COUNTIF('08-26'!G18:AO18,"TP")+COUNTIF('08-26'!F19:AO19,"TP")+COUNTIF('08-26'!F20:AO20,"TP")+COUNTIF('08-26'!G21:AO21,"TP")+COUNTIF('08-26'!F22:AO22,"TP")+COUNTIF('08-26'!G23:AO23,"TP")+COUNTIF('08-26'!G24:AO24,"TP")+COUNTIF('08-26'!G25:AO25,"TP")+COUNTIF('08-26'!G26:AO26,"TP")+COUNTIF('08-26'!G27:AO27,"TP")+COUNTIF('08-26'!G28:AO28,"TP"),COUNTIF(INDIRECT("'08-26'!G"&VLOOKUP($E$4,$AC$5:$AD$25,2,FALSE())&":AO"&VLOOKUP($E$4,$AC$5:$AD$25,2,FALSE())),"TP")) -> 0 | K8: =IF($E$4="TOUS",COUNTIF('09-26'!G10:AO10,"TP")+COUNTIF('09-26'!G9:AO9,"TP")+COUNTIF('09-26'!G8:AO8,"TP")+COUNTIF('09-26'!F11:AO11,"TP")+COUNTIF('09-26'!F12:AO12,"TP")+COUNTIF('09-26'!G13:AO13,"TP")+COUNTIF('09-26'!G14:AO14,"TP")+COUNTIF('09-26'!F15:AO15,"TP")+COUNTIF('09-26'!F16:AO16,"TP")+COUNTIF('09-26'!F17:AO17,"TP")+COUNTIF('09-26'!F18:AO18,"TP")+COUNTIF('09-26'!G19:AO19,"TP")+COUNTIF('09-26'!G20:AO20,"TP")+COUNTIF('09-26'!F21:AO21,"TP")+COUNTIF('09-26'!G22:AO22,"TP")+COUNTIF('09-26'!G23:AO23,"TP")+COUNTIF('09-26'!G24:AO24,"TP")+COUNTIF('09-26'!G25:AO25,"TP")+COUNTIF('09-26'!G26:AO26,"TP")+COUNTIF('09-26'!G27:AO27,"TP")+COUNTIF('09-26'!G28:AO28,"TP"),COUNTIF(INDIRECT("'09-26'!G"&VLOOKUP($E$4,$AC$5:$AD$25,2,FALSE())&":AO"&VLOOKUP($E$4,$AC$5:$AD$25,2,FALSE())),"TP")) -> 30 | L8: =IF($E$4="TOUS",COUNTIF('10-26'!G10:AO10,"TP")+COUNTIF('10-26'!G9:AO9,"TP")+COUNTIF('10-26'!G8:AO8,"TP")+COUNTIF('10-26'!F11:AO11,"TP")+COUNTIF('10-26'!F12:AO12,"TP")+COUNTIF('10-26'!G13:AO13,"TP")+COUNTIF('10-26'!F14:AO14,"TP")+COUNTIF('10-26'!F15:AO15,"TP")+COUNTIF('10-26'!F16:AO16,"TP")+COUNTIF('10-26'!F17:AO17,"TP")+COUNTIF('10-26'!G18:AO18,"TP")+COUNTIF('10-26'!G19:AO19,"TP")+COUNTIF('10-26'!F20:AO20,"TP")+COUNTIF('10-26'!G21:AO21,"TP")+COUNTIF('10-26'!G22:AO22,"TP")+COUNTIF('10-26'!F23:AO23,"TP")+COUNTIF('10-26'!G24:AO24,"TP")+COUNTIF('10-26'!G25:AO25,"TP")+COUNTIF('10-26'!G26:AO26,"TP")+COUNTIF('10-26'!G27:AO27,"TP")+COUNTIF('10-26'!G28:AO28,"TP"),COUNTIF(INDIRECT("'10-26'!G"&VLOOKUP($E$4,$AC$5:$AD$25,2,FALSE())&":AO"&VLOOKUP($E$4,$AC$5:$AD$25,2,FALSE())),"TP")) -> 15 | M8: =IF($E$4="TOUS",COUNTIF('11-26'!G10:AO10,"TP")+COUNTIF('11-26'!G9:AO9,"TP")+COUNTIF('11-26'!G8:AO8,"TP")+COUNTIF('11-26'!G11:AO11,"TP")+COUNTIF('11-26'!F12:AO12,"TP")+COUNTIF('11-26'!G13:AO13,"TP")+COUNTIF('11-26'!F14:AO14,"TP")+COUNTIF('11-26'!F15:AO15,"TP")+COUNTIF('11-26'!G16:AO16,"TP")+COUNTIF('11-26'!G17:AO17,"TP")+COUNTIF('11-26'!G18:AO18,"TP")+COUNTIF('11-26'!G19:AO19,"TP")+COUNTIF('11-26'!F20:AO20,"TP")+COUNTIF('11-26'!F21:AO21,"TP")+COUNTIF('11-26'!F22:AO22,"TP")+COUNTIF('11-26'!G23:AO23,"TP")+COUNTIF('11-26'!G24:AO24,"TP")+COUNTIF('11-26'!G25:AO25,"TP")+COUNTIF('11-26'!G26:AO26,"TP")+COUNTIF('11-26'!G27:AO27,"TP")+COUNTIF('11-26'!G28:AO28,"TP"),COUNTIF(INDIRECT("'11-26'!G"&VLOOKUP($E$4,$AC$5:$AD$25,2,FALSE())&":AO"&VLOOKUP($E$4,$AC$5:$AD$25,2,FALSE())),"TP")) -> 14 | N8: =IF($E$4="TOUS",COUNTIF('12-26'!G10:AO10,"TP")+COUNTIF('12-26'!G9:AO9,"TP")+COUNTIF('12-26'!G8:AO8,"TP")+COUNTIF('12-26'!G11:AO11,"TP")+COUNTIF('12-26'!G12:AO12,"TP")+COUNTIF('12-26'!G13:AO13,"TP")+COUNTIF('12-26'!G14:AO14,"TP")+COUNTIF('12-26'!F15:AO15,"TP")+COUNTIF('12-26'!G16:AO16,"TP")+COUNTIF('12-26'!F17:AO17,"TP")+COUNTIF('12-26'!G18:AO18,"TP")+COUNTIF('12-26'!G19:AO19,"TP")+COUNTIF('12-26'!F20:AO20,"TP")+COUNTIF('12-26'!F21:AO21,"TP")+COUNTIF('12-26'!F22:AO22,"TP")+COUNTIF('12-26'!G23:AO23,"TP")+COUNTIF('12-26'!G24:AO24,"TP")+COUNTIF('12-26'!G25:AO25,"TP")+COUNTIF('12-26'!G26:AO26,"TP")+COUNTIF('12-26'!G27:AO27,"TP")+COUNTIF('12-26'!G28:AO28,"TP"),COUNTIF(INDIRECT("'12-26'!G"&VLOOKUP($E$4,$AC$5:$AD$25,2,FALSE())&":AO"&VLOOKUP($E$4,$AC$5:$AD$25,2,FALSE())),"TP")) -> 19 | O8: =SUM(C8:N8) -> 173 | Q8: BARNEIX J. | R8: =COUNTIF('01-26'!G10:AO10,"TP")+COUNTIF('02-26'!G10:AO10,"TP")+COUNTIF('03-26'!G10:AO10,"TP")+COUNTIF('04-26'!G10:AO10,"TP")+COUNTIF('05-26'!G10:AO10,"TP")+COUNTIF('06-26'!G10:AO10,"TP")+COUNTIF('07-26'!G10:AO10,"TP")+COUNTIF('08-26'!G10:AO10,"TP")+COUNTIF('09-26'!G10:AO10,"TP")+COUNTIF('10-26'!G10:AO10,"TP")+COUNTIF('11-26'!G10:AO10,"TP")+COUNTIF('12-26'!G10:AO10,"TP") -> 86 | S8: =COUNTIF('01-26'!G10:AO10,"CSE")+COUNTIF('01-26'!G10:AO10,"CSE/RPX")+COUNTIF('01-26'!G10:AO10,"RPX")+COUNTIF('02-26'!G10:AO10,"CSE")+COUNTIF('02-26'!G10:AO10,"CSE/RPX")+COUNTIF('02-26'!G10:AO10,"RPX")+COUNTIF('03-26'!G10:AO10,"CSE")+COUNTIF('03-26'!G10:AO10,"CSE/RPX")+COUNTIF('03-26'!G10:AO10,"RPX")+COUNTIF('04-26'!G10:AO10,"CSE")+COUNTIF('04-26'!G10:AO10,"CSE/RPX")+COUNTIF('04-26'!G10:AO10,"RPX")+COUNTIF('05-26'!G10:AO10,"CSE")+COUNTIF('05-26'!G10:AO10,"CSE/RPX")+COUNTIF('05-26'!G10:AO10,"RPX")+COUNTIF('06-26'!G10:AO10,"CSE")+COUNTIF('06-26'!G10:AO10,"CSE/RPX")+COUNTIF('06-26'!G10:AO10,"RPX")+COUNTIF('07-26'!G10:AO10,"CSE")+COUNTIF('07-26'!G10:AO10,"CSE/RPX")+COUNTIF('07-26'!G10:AO10,"RPX")+COUNTIF('08-26'!G10:AO10,"CSE")+COUNTIF('08-26'!G10:AO10,"CSE/RPX")+COUNTIF('08-26'!G10:AO10,"RPX")+COUNTIF('09-26'!G10:AO10,"CSE")+COUNTIF('09-26'!G10:AO10,"CSE/RPX")+COUNTIF('09-26'!G10:AO10,"RPX")+COUNTIF('10-26'!G10:AO10,"CSE")+COUNTIF('10-26'!G10:AO10,"CSE/RPX")+COUNTIF('10-26'!G10:AO10,"RPX")+COUNTIF('11-26'!G10:AO10,"CSE")+COUNTIF('11-26'!G10:AO10,"CSE/RPX")+COUNTIF('11-26'!G10:AO10,"RPX")+COUNTIF('12-26'!G10:AO10,"CSE")+COUNTIF('12-26'!G10:AO10,"CSE/RPX")+COUNTIF('12-26'!G10:AO10,"RPX") -> 0 | T8: =COUNTIF('01-26'!G10:AO10,"CA/RC")+COUNTIF('01-26'!G10:AO10,"CA")+COUNTIF('02-26'!G10:AO10,"CA/RC")+COUNTIF('02-26'!G10:AO10,"CA")+COUNTIF('03-26'!G10:AO10,"CA/RC")+COUNTIF('03-26'!G10:AO10,"CA")+COUNTIF('04-26'!G10:AO10,"CA/RC")+COUNTIF('04-26'!G10:AO10,"CA")+COUNTIF('05-26'!G10:AO10,"CA/RC")+COUNTIF('05-26'!G10:AO10,"CA")+COUNTIF('06-26'!G10:AO10,"CA/RC")+COUNTIF('06-26'!G10:AO10,"CA")+COUNTIF('07-26'!G10:AO10,"CA/RC")+COUNTIF('07-26'!G10:AO10,"CA")+COUNTIF('08-26'!G10:AO10,"CA/RC")+COUNTIF('08-26'!G10:AO10,"CA")+COUNTIF('09-26'!G10:AO10,"CA/RC")+COUNTIF('09-26'!G10:AO10,"CA")+COUNTIF('10-26'!G10:AO10,"CA/RC")+COUNTIF('10-26'!G10:AO10,"CA")+COUNTIF('11-26'!G10:AO10,"CA/RC")+COUNTIF('11-26'!G10:AO10,"CA")+COUNTIF('12-26'!G10:AO10,"CA/RC")+COUNTIF('12-26'!G10:AO10,"CA") -> 24 | U8: =COUNTIF('01-26'!G10:AO10,"ATM/ATA")+COUNTIF('01-26'!G10:AO10,"ATM")+COUNTIF('01-26'!G10:AO10,"ATA")+COUNTIF('02-26'!G10:AO10,"ATM/ATA")+COUNTIF('02-26'!G10:AO10,"ATM")+COUNTIF('02-26'!G10:AO10,"ATA")+COUNTIF('03-26'!G10:AO10,"ATM/ATA")+COUNTIF('03-26'!G10:AO10,"ATM")+COUNTIF('03-26'!G10:AO10,"ATA")+COUNTIF('04-26'!G10:AO10,"ATM/ATA")+COUNTIF('04-26'!G10:AO10,"ATM")+COUNTIF('04-26'!G10:AO10,"ATA")+COUNTIF('05-26'!G10:AO10,"ATM/ATA")+COUNTIF('05-26'!G10:AO10,"ATM")+COUNTIF('05-26'!G10:AO10,"ATA")+COUNTIF('06-26'!G10:AO10,"ATM/ATA")+COUNTIF('06-26'!G10:AO10,"ATM")+COUNTIF('06-26'!G10:AO10,"ATA")+COUNTIF('07-26'!G10:AO10,"ATM/ATA")+COUNTIF('07-26'!G10:AO10,"ATM")+COUNTIF('07-26'!G10:AO10,"ATA")+COUNTIF('08-26'!G10:AO10,"ATM/ATA")+COUNTIF('08-26'!G10:AO10,"ATM")+COUNTIF('08-26'!G10:AO10,"ATA")+COUNTIF('09-26'!G10:AO10,"ATM/ATA")+COUNTIF('09-26'!G10:AO10,"ATM")+COUNTIF('09-26'!G10:AO10,"ATA")+COUNTIF('10-26'!G10:AO10,"ATM/ATA")+COUNTIF('10-26'!G10:AO10,"ATM")+COUNTIF('10-26'!G10:AO10,"ATA")+COUNTIF('11-26'!G10:AO10,"ATM/ATA")+COUNTIF('11-26'!G10:AO10,"ATM")+COUNTIF('11-26'!G10:AO10,"ATA")+COUNTIF('12-26'!G10:AO10,"ATM/ATA")+COUNTIF('12-26'!G10:AO10,"ATM")+COUNTIF('12-26'!G10:AO10,"ATA") -> 5 | V8: =COUNTIF('01-26'!G10:AO10,"ASA")+COUNTIF('02-26'!G10:AO10,"ASA")+COUNTIF('03-26'!G10:AO10,"ASA")+COUNTIF('04-26'!G10:AO10,"ASA")+COUNTIF('05-26'!G10:AO10,"ASA")+COUNTIF('06-26'!G10:AO10,"ASA")+COUNTIF('07-26'!G10:AO10,"ASA")+COUNTIF('08-26'!G10:AO10,"ASA")+COUNTIF('09-26'!G10:AO10,"ASA")+COUNTIF('10-26'!G10:AO10,"ASA")+COUNTIF('11-26'!G10:AO10,"ASA")+COUNTIF('12-26'!G10:AO10,"ASA") -> 0 | W8: =COUNTIF('01-26'!G10:AO10,"FORM")+COUNTIF('02-26'!G10:AO10,"FORM")+COUNTIF('03-26'!G10:AO10,"FORM")+COUNTIF('04-26'!G10:AO10,"FORM")+COUNTIF('05-26'!G10:AO10,"FORM")+COUNTIF('06-26'!G10:AO10,"FORM")+COUNTIF('07-26'!G10:AO10,"FORM")+COUNTIF('08-26'!G10:AO10,"FORM")+COUNTIF('09-26'!G10:AO10,"FORM")+COUNTIF('10-26'!G10:AO10,"FORM")+COUNTIF('11-26'!G10:AO10,"FORM")+COUNTIF('12-26'!G10:AO10,"FORM") -> 0 | X8: =COUNTIF('01-26'!G10:AO10,"RPM")+COUNTIF('01-26'!G10:AO10,"JPS")+COUNTIF('02-26'!G10:AO10,"RPM")+COUNTIF('02-26'!G10:AO10,"JPS")+COUNTIF('03-26'!G10:AO10,"RPM")+COUNTIF('03-26'!G10:AO10,"JPS")+COUNTIF('04-26'!G10:AO10,"RPM")+COUNTIF('04-26'!G10:AO10,"JPS")+COUNTIF('05-26'!G10:AO10,"RPM")+COUNTIF('05-26'!G10:AO10,"JPS")+COUNTIF('06-26'!G10:AO10,"RPM")+COUNTIF('06-26'!G10:AO10,"JPS")+COUNTIF('07-26'!G10:AO10,"RPM")+COUNTIF('07-26'!G10:AO10,"JPS")+COUNTIF('08-26'!G10:AO10,"RPM")+COUNTIF('08-26'!G10:AO10,"JPS")+COUNTIF('09-26'!G10:AO10,"RPM")+COUNTIF('09-26'!G10:AO10,"JPS")+COUNTIF('10-26'!G10:AO10,"RPM")+COUNTIF('10-26'!G10:AO10,"JPS")+COUNTIF('11-26'!G10:AO10,"RPM")+COUNTIF('11-26'!G10:AO10,"JPS")+COUNTIF('12-26'!G10:AO10,"RPM")+COUNTIF('12-26'!G10:AO10,"JPS") -> 0 | Y8: =SUM(R8:X8) -> 115 | AB8: LENEVEU N. | AC8: BAUDET R. | AD8: 11
B9: CSE/RPX | C9: =IF($E$4="TOUS",COUNTIF('01-26'!G10:AO10,"CSE")+COUNTIF('01-26'!G9:AO9,"CSE")+COUNTIF('01-26'!G8:AO8,"CSE")+COUNTIF('01-26'!G11:AO11,"CSE")+COUNTIF('01-26'!G12:AO12,"CSE")+COUNTIF('01-26'!G13:AO13,"CSE")+COUNTIF('01-26'!F14:AO14,"CSE")+COUNTIF('01-26'!G15:AO15,"CSE")+COUNTIF('01-26'!F16:AO16,"CSE")+COUNTIF('01-26'!F17:AO17,"CSE")+COUNTIF('01-26'!G18:AO18,"CSE")+COUNTIF('01-26'!G19:AO19,"CSE")+COUNTIF('01-26'!F20:AO20,"CSE")+COUNTIF('01-26'!F21:AO21,"CSE")+COUNTIF('01-26'!G22:AO22,"CSE")+COUNTIF('01-26'!G23:AO23,"CSE")+COUNTIF('01-26'!G24:AO24,"CSE")+COUNTIF('01-26'!G25:AO25,"CSE")+COUNTIF('01-26'!G26:AO26,"CSE")+COUNTIF('01-26'!G27:AO27,"CSE")+COUNTIF('01-26'!G28:AO28,"CSE")+COUNTIF('01-26'!G10:AO10,"CSE/RPX")+COUNTIF('01-26'!G9:AO9,"CSE/RPX")+COUNTIF('01-26'!G8:AO8,"CSE/RPX")+COUNTIF('01-26'!G11:AO11,"CSE/RPX")+COUNTIF('01-26'!G12:AO12,"CSE/RPX")+COUNTIF('01-26'!G13:AO13,"CSE/RPX")+COUNTIF('01-26'!F14:AO14,"CSE/RPX")+COUNTIF('01-26'!G15:AO15,"CSE/RPX")+COUNTIF('01-26'!F16:AO16,"CSE/RPX")+COUNTIF('01-26'!F17:AO17,"CSE/RPX")+COUNTIF('01-26'!G18:AO18,"CSE/RPX")+COUNTIF('01-26'!G19:AO19,"CSE/RPX")+COUNTIF('01-26'!F20:AO20,"CSE/RPX")+COUNTIF('01-26'!F21:AO21,"CSE/RPX")+COUNTIF('01-26'!G22:AO22,"CSE/RPX")+COUNTIF('01-26'!G23:AO23,"CSE/RPX")+COUNTIF('01-26'!G24:AO24,"CSE/RPX")+COUNTIF('01-26'!G25:AO25,"CSE/RPX")+COUNTIF('01-26'!G26:AO26,"CSE/RPX")+COUNTIF('01-26'!G27:AO27,"CSE/RPX")+COUNTIF('01-26'!G28:AO28,"CSE/RPX")+COUNTIF('01-26'!G10:AO10,"RPX")+COUNTIF('01-26'!G9:AO9,"RPX")+COUNTIF('01-26'!G8:AO8,"RPX")+COUNTIF('01-26'!G11:AO11,"RPX")+COUNTIF('01-26'!G12:AO12,"RPX")+COUNTIF('01-26'!G13:AO13,"RPX")+COUNTIF('01-26'!F14:AO14,"RPX")+COUNTIF('01-26'!G15:AO15,"RPX")+COUNTIF('01-26'!F16:AO16,"RPX")+COUNTIF('01-26'!F17:AO17,"RPX")+COUNTIF('01-26'!G18:AO18,"RPX")+COUNTIF('01-26'!G19:AO19,"RPX")+COUNTIF('01-26'!F20:AO20,"RPX")+COUNTIF('01-26'!F21:AO21,"RPX")+COUNTIF('01-26'!G22:AO22,"RPX")+COUNTIF('01-26'!G23:AO23,"RPX")+COUNTIF('01-26'!G24:AO24,"RPX")+COUNTIF('01-26'!G25:AO25,"RPX")+COUNTIF('01-26'!G26:AO26,"RPX")+COUNTIF('01-26'!G27:AO27,"RPX")+COUNTIF('01-26'!G28:AO28,"RPX"),COUNTIF(INDIRECT("'01-26'!G"&VLOOKUP($E$4,$AC$5:$AD$25,2,FALSE())&":AO"&VLOOKUP($E$4,$AC$5:$AD$25,2,FALSE())),"CSE")+COUNTIF(INDIRECT("'01-26'!G"&VLOOKUP($E$4,$AC$5:$AD$25,2,FALSE())&":AO"&VLOOKUP($E$4,$AC$5:$AD$25,2,FALSE())),"CSE/RPX")+COUNTIF(INDIRECT("'01-26'!G"&VLOOKUP($E$4,$AC$5:$AD$25,2,FALSE())&":AO"&VLOOKUP($E$4,$AC$5:$AD$25,2,FALSE())),"RPX")) -> 10 | D9: =IF($E$4="TOUS",COUNTIF('02-26'!G10:AO10,"CSE")+COUNTIF('02-26'!G9:AO9,"CSE")+COUNTIF('02-26'!G8:AO8,"CSE")+COUNTIF('02-26'!G11:AO11,"CSE")+COUNTIF('02-26'!F12:AO12,"CSE")+COUNTIF('02-26'!G13:AO13,"CSE")+COUNTIF('02-26'!G14:AO14,"CSE")+COUNTIF('02-26'!F15:AO15,"CSE")+COUNTIF('02-26'!G16:AO16,"CSE")+COUNTIF('02-26'!F17:AO17,"CSE")+COUNTIF('02-26'!G18:AO18,"CSE")+COUNTIF('02-26'!G19:AO19,"CSE")+COUNTIF('02-26'!F20:AO20,"CSE")+COUNTIF('02-26'!G21:AO21,"CSE")+COUNTIF('02-26'!G22:AO22,"CSE")+COUNTIF('02-26'!G23:AO23,"CSE")+COUNTIF('02-26'!G24:AO24,"CSE")+COUNTIF('02-26'!G25:AO25,"CSE")+COUNTIF('02-26'!G26:AO26,"CSE")+COUNTIF('02-26'!G27:AO27,"CSE")+COUNTIF('02-26'!G28:AO28,"CSE")+COUNTIF('02-26'!G10:AO10,"CSE/RPX")+COUNTIF('02-26'!G9:AO9,"CSE/RPX")+COUNTIF('02-26'!G8:AO8,"CSE/RPX")+COUNTIF('02-26'!G11:AO11,"CSE/RPX")+COUNTIF('02-26'!F12:AO12,"CSE/RPX")+COUNTIF('02-26'!G13:AO13,"CSE/RPX")+COUNTIF('02-26'!G14:AO14,"CSE/RPX")+COUNTIF('02-26'!F15:AO15,"CSE/RPX")+COUNTIF('02-26'!G16:AO16,"CSE/RPX")+COUNTIF('02-26'!F17:AO17,"CSE/RPX")+COUNTIF('02-26'!G18:AO18,"CSE/RPX")+COUNTIF('02-26'!G19:AO19,"CSE/RPX")+COUNTIF('02-26'!F20:AO20,"CSE/RPX")+COUNTIF('02-26'!G21:AO21,"CSE/RPX")+COUNTIF('02-26'!G22:AO22,"CSE/RPX")+COUNTIF('02-26'!G23:AO23,"CSE/RPX")+COUNTIF('02-26'!G24:AO24,"CSE/RPX")+COUNTIF('02-26'!G25:AO25,"CSE/RPX")+COUNTIF('02-26'!G26:AO26,"CSE/RPX")+COUNTIF('02-26'!G27:AO27,"CSE/RPX")+COUNTIF('02-26'!G28:AO28,"CSE/RPX")+COUNTIF('02-26'!G10:AO10,"RPX")+COUNTIF('02-26'!G9:AO9,"RPX")+COUNTIF('02-26'!G8:AO8,"RPX")+COUNTIF('02-26'!G11:AO11,"RPX")+COUNTIF('02-26'!F12:AO12,"RPX")+COUNTIF('02-26'!G13:AO13,"RPX")+COUNTIF('02-26'!G14:AO14,"RPX")+COUNTIF('02-26'!F15:AO15,"RPX")+COUNTIF('02-26'!G16:AO16,"RPX")+COUNTIF('02-26'!F17:AO17,"RPX")+COUNTIF('02-26'!G18:AO18,"RPX")+COUNTIF('02-26'!G19:AO19,"RPX")+COUNTIF('02-26'!F20:AO20,"RPX")+COUNTIF('02-26'!G21:AO21,"RPX")+COUNTIF('02-26'!G22:AO22,"RPX")+COUNTIF('02-26'!G23:AO23,"RPX")+COUNTIF('02-26'!G24:AO24,"RPX")+COUNTIF('02-26'!G25:AO25,"RPX")+COUNTIF('02-26'!G26:AO26,"RPX")+COUNTIF('02-26'!G27:AO27,"RPX")+COUNTIF('02-26'!G28:AO28,"RPX"),COUNTIF(INDIRECT("'02-26'!G"&VLOOKUP($E$4,$AC$5:$AD$25,2,FALSE())&":AO"&VLOOKUP($E$4,$AC$5:$AD$25,2,FALSE())),"CSE")+COUNTIF(INDIRECT("'02-26'!G"&VLOOKUP($E$4,$AC$5:$AD$25,2,FALSE())&":AO"&VLOOKUP($E$4,$AC$5:$AD$25,2,FALSE())),"CSE/RPX")+COUNTIF(INDIRECT("'02-26'!G"&VLOOKUP($E$4,$AC$5:$AD$25,2,FALSE())&":AO"&VLOOKUP($E$4,$AC$5:$AD$25,2,FALSE())),"RPX")) -> 5 | E9: =IF($E$4="TOUS",COUNTIF('03-26'!G10:AO10,"CSE")+COUNTIF('03-26'!G9:AO9,"CSE")+COUNTIF('03-26'!G8:AO8,"CSE")+COUNTIF('03-26'!G11:AO11,"CSE")+COUNTIF('03-26'!F12:AO12,"CSE")+COUNTIF('03-26'!G13:AO13,"CSE")+COUNTIF('03-26'!G14:AO14,"CSE")+COUNTIF('03-26'!F15:AO15,"CSE")+COUNTIF('03-26'!F16:AO16,"CSE")+COUNTIF('03-26'!F17:AO17,"CSE")+COUNTIF('03-26'!F18:AO18,"CSE")+COUNTIF('03-26'!G19:AO19,"CSE")+COUNTIF('03-26'!G20:AO20,"CSE")+COUNTIF('03-26'!G21:AO21,"CSE")+COUNTIF('03-26'!F22:AO22,"CSE")+COUNTIF('03-26'!G23:AO23,"CSE")+COUNTIF('03-26'!G24:AO24,"CSE")+COUNTIF('03-26'!G25:AO25,"CSE")+COUNTIF('03-26'!G26:AO26,"CSE")+COUNTIF('03-26'!G27:AO27,"CSE")+COUNTIF('03-26'!G28:AO28,"CSE")+COUNTIF('03-26'!G10:AO10,"CSE/RPX")+COUNTIF('03-26'!G9:AO9,"CSE/RPX")+COUNTIF('03-26'!G8:AO8,"CSE/RPX")+COUNTIF('03-26'!G11:AO11,"CSE/RPX")+COUNTIF('03-26'!F12:AO12,"CSE/RPX")+COUNTIF('03-26'!G13:AO13,"CSE/RPX")+COUNTIF('03-26'!G14:AO14,"CSE/RPX")+COUNTIF('03-26'!F15:AO15,"CSE/RPX")+COUNTIF('03-26'!F16:AO16,"CSE/RPX")+COUNTIF('03-26'!F17:AO17,"CSE/RPX")+COUNTIF('03-26'!F18:AO18,"CSE/RPX")+COUNTIF('03-26'!G19:AO19,"CSE/RPX")+COUNTIF('03-26'!G20:AO20,"CSE/RPX")+COUNTIF('03-26'!G21:AO21,"CSE/RPX")+COUNTIF('03-26'!F22:AO22,"CSE/RPX")+COUNTIF('03-26'!G23:AO23,"CSE/RPX")+COUNTIF('03-26'!G24:AO24,"CSE/RPX")+COUNTIF('03-26'!G25:AO25,"CSE/RPX")+COUNTIF('03-26'!G26:AO26,"CSE/RPX")+COUNTIF('03-26'!G27:AO27,"CSE/RPX")+COUNTIF('03-26'!G28:AO28,"CSE/RPX")+COUNTIF('03-26'!G10:AO10,"RPX")+COUNTIF('03-26'!G9:AO9,"RPX")+COUNTIF('03-26'!G8:AO8,"RPX")+COUNTIF('03-26'!G11:AO11,"RPX")+COUNTIF('03-26'!F12:AO12,"RPX")+COUNTIF('03-26'!G13:AO13,"RPX")+COUNTIF('03-26'!G14:AO14,"RPX")+COUNTIF('03-26'!F15:AO15,"RPX")+COUNTIF('03-26'!F16:AO16,"RPX")+COUNTIF('03-26'!F17:AO17,"RPX")+COUNTIF('03-26'!F18:AO18,"RPX")+COUNTIF('03-26'!G19:AO19,"RPX")+COUNTIF('03-26'!G20:AO20,"RPX")+COUNTIF('03-26'!G21:AO21,"RPX")+COUNTIF('03-26'!F22:AO22,"RPX")+COUNTIF('03-26'!G23:AO23,"RPX")+COUNTIF('03-26'!G24:AO24,"RPX")+COUNTIF('03-26'!G25:AO25,"RPX")+COUNTIF('03-26'!G26:AO26,"RPX")+COUNTIF('03-26'!G27:AO27,"RPX")+COUNTIF('03-26'!G28:AO28,"RPX"),COUNTIF(INDIRECT("'03-26'!G"&VLOOKUP($E$4,$AC$5:$AD$25,2,FALSE())&":AO"&VLOOKUP($E$4,$AC$5:$AD$25,2,FALSE())),"CSE")+COUNTIF(INDIRECT("'03-26'!G"&VLOOKUP($E$4,$AC$5:$AD$25,2,FALSE())&":AO"&VLOOKUP($E$4,$AC$5:$AD$25,2,FALSE())),"CSE/RPX")+COUNTIF(INDIRECT("'03-26'!G"&VLOOKUP($E$4,$AC$5:$AD$25,2,FALSE())&":AO"&VLOOKUP($E$4,$AC$5:$AD$25,2,FALSE())),"RPX")) -> 3 | F9: =IF($E$4="TOUS",COUNTIF('04-26'!G10:AO10,"CSE")+COUNTIF('04-26'!G9:AO9,"CSE")+COUNTIF('04-26'!G8:AO8,"CSE")+COUNTIF('04-26'!G11:AO11,"CSE")+COUNTIF('04-26'!F12:AO12,"CSE")+COUNTIF('04-26'!G13:AO13,"CSE")+COUNTIF('04-26'!F14:AO14,"CSE")+COUNTIF('04-26'!G15:AO15,"CSE")+COUNTIF('04-26'!G16:AO16,"CSE")+COUNTIF('04-26'!G17:AO17,"CSE")+COUNTIF('04-26'!G18:AO18,"CSE")+COUNTIF('04-26'!G19:AO19,"CSE")+COUNTIF('04-26'!G20:AO20,"CSE")+COUNTIF('04-26'!G21:AO21,"CSE")+COUNTIF('04-26'!G22:AO22,"CSE")+COUNTIF('04-26'!G23:AO23,"CSE")+COUNTIF('04-26'!G24:AO24,"CSE")+COUNTIF('04-26'!G25:AO25,"CSE")+COUNTIF('04-26'!G26:AO26,"CSE")+COUNTIF('04-26'!G27:AO27,"CSE")+COUNTIF('04-26'!G28:AO28,"CSE")+COUNTIF('04-26'!G10:AO10,"CSE/RPX")+COUNTIF('04-26'!G9:AO9,"CSE/RPX")+COUNTIF('04-26'!G8:AO8,"CSE/RPX")+COUNTIF('04-26'!G11:AO11,"CSE/RPX")+COUNTIF('04-26'!F12:AO12,"CSE/RPX")+COUNTIF('04-26'!G13:AO13,"CSE/RPX")+COUNTIF('04-26'!F14:AO14,"CSE/RPX")+COUNTIF('04-26'!G15:AO15,"CSE/RPX")+COUNTIF('04-26'!G16:AO16,"CSE/RPX")+COUNTIF('04-26'!G17:AO17,"CSE/RPX")+COUNTIF('04-26'!G18:AO18,"CSE/RPX")+COUNTIF('04-26'!G19:AO19,"CSE/RPX")+COUNTIF('04-26'!G20:AO20,"CSE/RPX")+COUNTIF('04-26'!G21:AO21,"CSE/RPX")+COUNTIF('04-26'!G22:AO22,"CSE/RPX")+COUNTIF('04-26'!G23:AO23,"CSE/RPX")+COUNTIF('04-26'!G24:AO24,"CSE/RPX")+COUNTIF('04-26'!G25:AO25,"CSE/RPX")+COUNTIF('04-26'!G26:AO26,"CSE/RPX")+COUNTIF('04-26'!G27:AO27,"CSE/RPX")+COUNTIF('04-26'!G28:AO28,"CSE/RPX")+COUNTIF('04-26'!G10:AO10,"RPX")+COUNTIF('04-26'!G9:AO9,"RPX")+COUNTIF('04-26'!G8:AO8,"RPX")+COUNTIF('04-26'!G11:AO11,"RPX")+COUNTIF('04-26'!F12:AO12,"RPX")+COUNTIF('04-26'!G13:AO13,"RPX")+COUNTIF('04-26'!F14:AO14,"RPX")+COUNTIF('04-26'!G15:AO15,"RPX")+COUNTIF('04-26'!G16:AO16,"RPX")+COUNTIF('04-26'!G17:AO17,"RPX")+COUNTIF('04-26'!G18:AO18,"RPX")+COUNTIF('04-26'!G19:AO19,"RPX")+COUNTIF('04-26'!G20:AO20,"RPX")+COUNTIF('04-26'!G21:AO21,"RPX")+COUNTIF('04-26'!G22:AO22,"RPX")+COUNTIF('04-26'!G23:AO23,"RPX")+COUNTIF('04-26'!G24:AO24,"RPX")+COUNTIF('04-26'!G25:AO25,"RPX")+COUNTIF('04-26'!G26:AO26,"RPX")+COUNTIF('04-26'!G27:AO27,"RPX")+COUNTIF('04-26'!G28:AO28,"RPX"),COUNTIF(INDIRECT("'04-26'!G"&VLOOKUP($E$4,$AC$5:$AD$25,2,FALSE())&":AO"&VLOOKUP($E$4,$AC$5:$AD$25,2,FALSE())),"CSE")+COUNTIF(INDIRECT("'04-26'!G"&VLOOKUP($E$4,$AC$5:$AD$25,2,FALSE())&":AO"&VLOOKUP($E$4,$AC$5:$AD$25,2,FALSE())),"CSE/RPX")+COUNTIF(INDIRECT("'04-26'!G"&VLOOKUP($E$4,$AC$5:$AD$25,2,FALSE())&":AO"&VLOOKUP($E$4,$AC$5:$AD$25,2,FALSE())),"RPX")) -> 8 | G9: =IF($E$4="TOUS",COUNTIF('05-26'!G10:AO10,"CSE")+COUNTIF('05-26'!G9:AO9,"CSE")+COUNTIF('05-26'!G8:AO8,"CSE")+COUNTIF('05-26'!G11:AO11,"CSE")+COUNTIF('05-26'!F12:AO12,"CSE")+COUNTIF('05-26'!G13:AO13,"CSE")+COUNTIF('05-26'!F14:AO14,"CSE")+COUNTIF('05-26'!F15:AO15,"CSE")+COUNTIF('05-26'!G16:AO16,"CSE")+COUNTIF('05-26'!F17:AO17,"CSE")+COUNTIF('05-26'!G18:AO18,"CSE")+COUNTIF('05-26'!G19:AO19,"CSE")+COUNTIF('05-26'!G20:AO20,"CSE")+COUNTIF('05-26'!F21:AO21,"CSE")+COUNTIF('05-26'!F22:AO22,"CSE")+COUNTIF('05-26'!G23:AO23,"CSE")+COUNTIF('05-26'!G24:AO24,"CSE")+COUNTIF('05-26'!G25:AO25,"CSE")+COUNTIF('05-26'!G26:AO26,"CSE")+COUNTIF('05-26'!G27:AO27,"CSE")+COUNTIF('05-26'!G28:AO28,"CSE")+COUNTIF('05-26'!G10:AO10,"CSE/RPX")+COUNTIF('05-26'!G9:AO9,"CSE/RPX")+COUNTIF('05-26'!G8:AO8,"CSE/RPX")+COUNTIF('05-26'!G11:AO11,"CSE/RPX")+COUNTIF('05-26'!F12:AO12,"CSE/RPX")+COUNTIF('05-26'!G13:AO13,"CSE/RPX")+COUNTIF('05-26'!F14:AO14,"CSE/RPX")+COUNTIF('05-26'!F15:AO15,"CSE/RPX")+COUNTIF('05-26'!G16:AO16,"CSE/RPX")+COUNTIF('05-26'!F17:AO17,"CSE/RPX")+COUNTIF('05-26'!G18:AO18,"CSE/RPX")+COUNTIF('05-26'!G19:AO19,"CSE/RPX")+COUNTIF('05-26'!G20:AO20,"CSE/RPX")+COUNTIF('05-26'!F21:AO21,"CSE/RPX")+COUNTIF('05-26'!F22:AO22,"CSE/RPX")+COUNTIF('05-26'!G23:AO23,"CSE/RPX")+COUNTIF('05-26'!G24:AO24,"CSE/RPX")+COUNTIF('05-26'!G25:AO25,"CSE/RPX")+COUNTIF('05-26'!G26:AO26,"CSE/RPX")+COUNTIF('05-26'!G27:AO27,"CSE/RPX")+COUNTIF('05-26'!G28:AO28,"CSE/RPX")+COUNTIF('05-26'!G10:AO10,"RPX")+COUNTIF('05-26'!G9:AO9,"RPX")+COUNTIF('05-26'!G8:AO8,"RPX")+COUNTIF('05-26'!G11:AO11,"RPX")+COUNTIF('05-26'!F12:AO12,"RPX")+COUNTIF('05-26'!G13:AO13,"RPX")+COUNTIF('05-26'!F14:AO14,"RPX")+COUNTIF('05-26'!F15:AO15,"RPX")+COUNTIF('05-26'!G16:AO16,"RPX")+COUNTIF('05-26'!F17:AO17,"RPX")+COUNTIF('05-26'!G18:AO18,"RPX")+COUNTIF('05-26'!G19:AO19,"RPX")+COUNTIF('05-26'!G20:AO20,"RPX")+COUNTIF('05-26'!F21:AO21,"RPX")+COUNTIF('05-26'!F22:AO22,"RPX")+COUNTIF('05-26'!G23:AO23,"RPX")+COUNTIF('05-26'!G24:AO24,"RPX")+COUNTIF('05-26'!G25:AO25,"RPX")+COUNTIF('05-26'!G26:AO26,"RPX")+COUNTIF('05-26'!G27:AO27,"RPX")+COUNTIF('05-26'!G28:AO28,"RPX"),COUNTIF(INDIRECT("'05-26'!G"&VLOOKUP($E$4,$AC$5:$AD$25,2,FALSE())&":AO"&VLOOKUP($E$4,$AC$5:$AD$25,2,FALSE())),"CSE")+COUNTIF(INDIRECT("'05-26'!G"&VLOOKUP($E$4,$AC$5:$AD$25,2,FALSE())&":AO"&VLOOKUP($E$4,$AC$5:$AD$25,2,FALSE())),"CSE/RPX")+COUNTIF(INDIRECT("'05-26'!G"&VLOOKUP($E$4,$AC$5:$AD$25,2,FALSE())&":AO"&VLOOKUP($E$4,$AC$5:$AD$25,2,FALSE())),"RPX")) -> 2 | H9: =IF($E$4="TOUS",COUNTIF('06-26'!G10:AO10,"CSE")+COUNTIF('06-26'!G9:AO9,"CSE")+COUNTIF('06-26'!G8:AO8,"CSE")+COUNTIF('06-26'!G11:AO11,"CSE")+COUNTIF('06-26'!F12:AO12,"CSE")+COUNTIF('06-26'!G13:AO13,"CSE")+COUNTIF('06-26'!F14:AO14,"CSE")+COUNTIF('06-26'!F15:AO15,"CSE")+COUNTIF('06-26'!F16:AO16,"CSE")+COUNTIF('06-26'!F17:AO17,"CSE")+COUNTIF('06-26'!G18:AO18,"CSE")+COUNTIF('06-26'!G19:AO19,"CSE")+COUNTIF('06-26'!G20:AO20,"CSE")+COUNTIF('06-26'!F21:AO21,"CSE")+COUNTIF('06-26'!F22:AO22,"CSE")+COUNTIF('06-26'!G23:AO23,"CSE")+COUNTIF('06-26'!G24:AO24,"CSE")+COUNTIF('06-26'!G25:AO25,"CSE")+COUNTIF('06-26'!G26:AO26,"CSE")+COUNTIF('06-26'!G27:AO27,"CSE")+COUNTIF('06-26'!G28:AO28,"CSE")+COUNTIF('06-26'!G10:AO10,"CSE/RPX")+COUNTIF('06-26'!G9:AO9,"CSE/RPX")+COUNTIF('06-26'!G8:AO8,"CSE/RPX")+COUNTIF('06-26'!G11:AO11,"CSE/RPX")+COUNTIF('06-26'!F12:AO12,"CSE/RPX")+COUNTIF('06-26'!G13:AO13,"CSE/RPX")+COUNTIF('06-26'!F14:AO14,"CSE/RPX")+COUNTIF('06-26'!F15:AO15,"CSE/RPX")+COUNTIF('06-26'!F16:AO16,"CSE/RPX")+COUNTIF('06-26'!F17:AO17,"CSE/RPX")+COUNTIF('06-26'!G18:AO18,"CSE/RPX")+COUNTIF('06-26'!G19:AO19,"CSE/RPX")+COUNTIF('06-26'!G20:AO20,"CSE/RPX")+COUNTIF('06-26'!F21:AO21,"CSE/RPX")+COUNTIF('06-26'!F22:AO22,"CSE/RPX")+COUNTIF('06-26'!G23:AO23,"CSE/RPX")+COUNTIF('06-26'!G24:AO24,"CSE/RPX")+COUNTIF('06-26'!G25:AO25,"CSE/RPX")+COUNTIF('06-26'!G26:AO26,"CSE/RPX")+COUNTIF('06-26'!G27:AO27,"CSE/RPX")+COUNTIF('06-26'!G28:AO28,"CSE/RPX")+COUNTIF('06-26'!G10:AO10,"RPX")+COUNTIF('06-26'!G9:AO9,"RPX")+COUNTIF('06-26'!G8:AO8,"RPX")+COUNTIF('06-26'!G11:AO11,"RPX")+COUNTIF('06-26'!F12:AO12,"RPX")+COUNTIF('06-26'!G13:AO13,"RPX")+COUNTIF('06-26'!F14:AO14,"RPX")+COUNTIF('06-26'!F15:AO15,"RPX")+COUNTIF('06-26'!F16:AO16,"RPX")+COUNTIF('06-26'!F17:AO17,"RPX")+COUNTIF('06-26'!G18:AO18,"RPX")+COUNTIF('06-26'!G19:AO19,"RPX")+COUNTIF('06-26'!G20:AO20,"RPX")+COUNTIF('06-26'!F21:AO21,"RPX")+COUNTIF('06-26'!F22:AO22,"RPX")+COUNTIF('06-26'!G23:AO23,"RPX")+COUNTIF('06-26'!G24:AO24,"RPX")+COUNTIF('06-26'!G25:AO25,"RPX")+COUNTIF('06-26'!G26:AO26,"RPX")+COUNTIF('06-26'!G27:AO27,"RPX")+COUNTIF('06-26'!G28:AO28,"RPX"),COUNTIF(INDIRECT("'06-26'!G"&VLOOKUP($E$4,$AC$5:$AD$25,2,FALSE())&":AO"&VLOOKUP($E$4,$AC$5:$AD$25,2,FALSE())),"CSE")+COUNTIF(INDIRECT("'06-26'!G"&VLOOKUP($E$4,$AC$5:$AD$25,2,FALSE())&":AO"&VLOOKUP($E$4,$AC$5:$AD$25,2,FALSE())),"CSE/RPX")+COUNTIF(INDIRECT("'06-26'!G"&VLOOKUP($E$4,$AC$5:$AD$25,2,FALSE())&":AO"&VLOOKUP($E$4,$AC$5:$AD$25,2,FALSE())),"RPX")) -> 1 | I9: =IF($E$4="TOUS",COUNTIF('07-26'!G10:AO10,"CSE")+COUNTIF('07-26'!G9:AO9,"CSE")+COUNTIF('07-26'!G8:AO8,"CSE")+COUNTIF('07-26'!F11:AO11,"CSE")+COUNTIF('07-26'!G12:AO12,"CSE")+COUNTIF('07-26'!G13:AO13,"CSE")+COUNTIF('07-26'!F14:AO14,"CSE")+COUNTIF('07-26'!F15:AO15,"CSE")+COUNTIF('07-26'!G16:AO16,"CSE")+COUNTIF('07-26'!G17:AO17,"CSE")+COUNTIF('07-26'!G18:AO18,"CSE")+COUNTIF('07-26'!G19:AO19,"CSE")+COUNTIF('07-26'!F20:AO20,"CSE")+COUNTIF('07-26'!F21:AO21,"CSE")+COUNTIF('07-26'!F22:AO22,"CSE")+COUNTIF('07-26'!G23:AO23,"CSE")+COUNTIF('07-26'!G24:AO24,"CSE")+COUNTIF('07-26'!G25:AO25,"CSE")+COUNTIF('07-26'!G26:AO26,"CSE")+COUNTIF('07-26'!G27:AO27,"CSE")+COUNTIF('07-26'!G28:AO28,"CSE")+COUNTIF('07-26'!G10:AO10,"CSE/RPX")+COUNTIF('07-26'!G9:AO9,"CSE/RPX")+COUNTIF('07-26'!G8:AO8,"CSE/RPX")+COUNTIF('07-26'!F11:AO11,"CSE/RPX")+COUNTIF('07-26'!G12:AO12,"CSE/RPX")+COUNTIF('07-26'!G13:AO13,"CSE/RPX")+COUNTIF('07-26'!F14:AO14,"CSE/RPX")+COUNTIF('07-26'!F15:AO15,"CSE/RPX")+COUNTIF('07-26'!G16:AO16,"CSE/RPX")+COUNTIF('07-26'!G17:AO17,"CSE/RPX")+COUNTIF('07-26'!G18:AO18,"CSE/RPX")+COUNTIF('07-26'!G19:AO19,"CSE/RPX")+COUNTIF('07-26'!F20:AO20,"CSE/RPX")+COUNTIF('07-26'!F21:AO21,"CSE/RPX")+COUNTIF('07-26'!F22:AO22,"CSE/RPX")+COUNTIF('07-26'!G23:AO23,"CSE/RPX")+COUNTIF('07-26'!G24:AO24,"CSE/RPX")+COUNTIF('07-26'!G25:AO25,"CSE/RPX")+COUNTIF('07-26'!G26:AO26,"CSE/RPX")+COUNTIF('07-26'!G27:AO27,"CSE/RPX")+COUNTIF('07-26'!G28:AO28,"CSE/RPX")+COUNTIF('07-26'!G10:AO10,"RPX")+COUNTIF('07-26'!G9:AO9,"RPX")+COUNTIF('07-26'!G8:AO8,"RPX")+COUNTIF('07-26'!F11:AO11,"RPX")+COUNTIF('07-26'!G12:AO12,"RPX")+COUNTIF('07-26'!G13:AO13,"RPX")+COUNTIF('07-26'!F14:AO14,"RPX")+COUNTIF('07-26'!F15:AO15,"RPX")+COUNTIF('07-26'!G16:AO16,"RPX")+COUNTIF('07-26'!G17:AO17,"RPX")+COUNTIF('07-26'!G18:AO18,"RPX")+COUNTIF('07-26'!G19:AO19,"RPX")+COUNTIF('07-26'!F20:AO20,"RPX")+COUNTIF('07-26'!F21:AO21,"RPX")+COUNTIF('07-26'!F22:AO22,"RPX")+COUNTIF('07-26'!G23:AO23,"RPX")+COUNTIF('07-26'!G24:AO24,"RPX")+COUNTIF('07-26'!G25:AO25,"RPX")+COUNTIF('07-26'!G26:AO26,"RPX")+COUNTIF('07-26'!G27:AO27,"RPX")+COUNTIF('07-26'!G28:AO28,"RPX"),COUNTIF(INDIRECT("'07-26'!G"&VLOOKUP($E$4,$AC$5:$AD$25,2,FALSE())&":AO"&VLOOKUP($E$4,$AC$5:$AD$25,2,FALSE())),"CSE")+COUNTIF(INDIRECT("'07-26'!G"&VLOOKUP($E$4,$AC$5:$AD$25,2,FALSE())&":AO"&VLOOKUP($E$4,$AC$5:$AD$25,2,FALSE())),"CSE/RPX")+COUNTIF(INDIRECT("'07-26'!G"&VLOOKUP($E$4,$AC$5:$AD$25,2,FALSE())&":AO"&VLOOKUP($E$4,$AC$5:$AD$25,2,FALSE())),"RPX")) -> 3 | J9: =IF($E$4="TOUS",COUNTIF('08-26'!G10:AO10,"CSE")+COUNTIF('08-26'!G9:AO9,"CSE")+COUNTIF('08-26'!G8:AO8,"CSE")+COUNTIF('08-26'!F11:AO11,"CSE")+COUNTIF('08-26'!F12:AO12,"CSE")+COUNTIF('08-26'!F13:AO13,"CSE")+COUNTIF('08-26'!F14:AO14,"CSE")+COUNTIF('08-26'!F15:AO15,"CSE")+COUNTIF('08-26'!G16:AO16,"CSE")+COUNTIF('08-26'!F17:AO17,"CSE")+COUNTIF('08-26'!G18:AO18,"CSE")+COUNTIF('08-26'!F19:AO19,"CSE")+COUNTIF('08-26'!F20:AO20,"CSE")+COUNTIF('08-26'!G21:AO21,"CSE")+COUNTIF('08-26'!F22:AO22,"CSE")+COUNTIF('08-26'!G23:AO23,"CSE")+COUNTIF('08-26'!G24:AO24,"CSE")+COUNTIF('08-26'!G25:AO25,"CSE")+COUNTIF('08-26'!G26:AO26,"CSE")+COUNTIF('08-26'!G27:AO27,"CSE")+COUNTIF('08-26'!G28:AO28,"CSE")+COUNTIF('08-26'!G10:AO10,"CSE/RPX")+COUNTIF('08-26'!G9:AO9,"CSE/RPX")+COUNTIF('08-26'!G8:AO8,"CSE/RPX")+COUNTIF('08-26'!F11:AO11,"CSE/RPX")+COUNTIF('08-26'!F12:AO12,"CSE/RPX")+COUNTIF('08-26'!F13:AO13,"CSE/RPX")+COUNTIF('08-26'!F14:AO14,"CSE/RPX")+COUNTIF('08-26'!F15:AO15,"CSE/RPX")+COUNTIF('08-26'!G16:AO16,"CSE/RPX")+COUNTIF('08-26'!F17:AO17,"CSE/RPX")+COUNTIF('08-26'!G18:AO18,"CSE/RPX")+COUNTIF('08-26'!F19:AO19,"CSE/RPX")+COUNTIF('08-26'!F20:AO20,"CSE/RPX")+COUNTIF('08-26'!G21:AO21,"CSE/RPX")+COUNTIF('08-26'!F22:AO22,"CSE/RPX")+COUNTIF('08-26'!G23:AO23,"CSE/RPX")+COUNTIF('08-26'!G24:AO24,"CSE/RPX")+COUNTIF('08-26'!G25:AO25,"CSE/RPX")+COUNTIF('08-26'!G26:AO26,"CSE/RPX")+COUNTIF('08-26'!G27:AO27,"CSE/RPX")+COUNTIF('08-26'!G28:AO28,"CSE/RPX")+COUNTIF('08-26'!G10:AO10,"RPX")+COUNTIF('08-26'!G9:AO9,"RPX")+COUNTIF('08-26'!G8:AO8,"RPX")+COUNTIF('08-26'!F11:AO11,"RPX")+COUNTIF('08-26'!F12:AO12,"RPX")+COUNTIF('08-26'!F13:AO13,"RPX")+COUNTIF('08-26'!F14:AO14,"RPX")+COUNTIF('08-26'!F15:AO15,"RPX")+COUNTIF('08-26'!G16:AO16,"RPX")+COUNTIF('08-26'!F17:AO17,"RPX")+COUNTIF('08-26'!G18:AO18,"RPX")+COUNTIF('08-26'!F19:AO19,"RPX")+COUNTIF('08-26'!F20:AO20,"RPX")+COUNTIF('08-26'!G21:AO21,"RPX")+COUNTIF('08-26'!F22:AO22,"RPX")+COUNTIF('08-26'!G23:AO23,"RPX")+COUNTIF('08-26'!G24:AO24,"RPX")+COUNTIF('08-26'!G25:AO25,"RPX")+COUNTIF('08-26'!G26:AO26,"RPX")+COUNTIF('08-26'!G27:AO27,"RPX")+COUNTIF('08-26'!G28:AO28,"RPX"),COUNTIF(INDIRECT("'08-26'!G"&VLOOKUP($E$4,$AC$5:$AD$25,2,FALSE())&":AO"&VLOOKUP($E$4,$AC$5:$AD$25,2,FALSE())),"CSE")+COUNTIF(INDIRECT("'08-26'!G"&VLOOKUP($E$4,$AC$5:$AD$25,2,FALSE())&":AO"&VLOOKUP($E$4,$AC$5:$AD$25,2,FALSE())),"CSE/RPX")+COUNTIF(INDIRECT("'08-26'!G"&VLOOKUP($E$4,$AC$5:$AD$25,2,FALSE())&":AO"&VLOOKUP($E$4,$AC$5:$AD$25,2,FALSE())),"RPX")) -> 0 | K9: =IF($E$4="TOUS",COUNTIF('09-26'!G10:AO10,"CSE")+COUNTIF('09-26'!G9:AO9,"CSE")+COUNTIF('09-26'!G8:AO8,"CSE")+COUNTIF('09-26'!F11:AO11,"CSE")+COUNTIF('09-26'!F12:AO12,"CSE")+COUNTIF('09-26'!G13:AO13,"CSE")+COUNTIF('09-26'!G14:AO14,"CSE")+COUNTIF('09-26'!F15:AO15,"CSE")+COUNTIF('09-26'!F16:AO16,"CSE")+COUNTIF('09-26'!F17:AO17,"CSE")+COUNTIF('09-26'!F18:AO18,"CSE")+COUNTIF('09-26'!G19:AO19,"CSE")+COUNTIF('09-26'!G20:AO20,"CSE")+COUNTIF('09-26'!F21:AO21,"CSE")+COUNTIF('09-26'!G22:AO22,"CSE")+COUNTIF('09-26'!G23:AO23,"CSE")+COUNTIF('09-26'!G24:AO24,"CSE")+COUNTIF('09-26'!G25:AO25,"CSE")+COUNTIF('09-26'!G26:AO26,"CSE")+COUNTIF('09-26'!G27:AO27,"CSE")+COUNTIF('09-26'!G28:AO28,"CSE")+COUNTIF('09-26'!G10:AO10,"CSE/RPX")+COUNTIF('09-26'!G9:AO9,"CSE/RPX")+COUNTIF('09-26'!G8:AO8,"CSE/RPX")+COUNTIF('09-26'!F11:AO11,"CSE/RPX")+COUNTIF('09-26'!F12:AO12,"CSE/RPX")+COUNTIF('09-26'!G13:AO13,"CSE/RPX")+COUNTIF('09-26'!G14:AO14,"CSE/RPX")+COUNTIF('09-26'!F15:AO15,"CSE/RPX")+COUNTIF('09-26'!F16:AO16,"CSE/RPX")+COUNTIF('09-26'!F17:AO17,"CSE/RPX")+COUNTIF('09-26'!F18:AO18,"CSE/RPX")+COUNTIF('09-26'!G19:AO19,"CSE/RPX")+COUNTIF('09-26'!G20:AO20,"CSE/RPX")+COUNTIF('09-26'!F21:AO21,"CSE/RPX")+COUNTIF('09-26'!G22:AO22,"CSE/RPX")+COUNTIF('09-26'!G23:AO23,"CSE/RPX")+COUNTIF('09-26'!G24:AO24,"CSE/RPX")+COUNTIF('09-26'!G25:AO25,"CSE/RPX")+COUNTIF('09-26'!G26:AO26,"CSE/RPX")+COUNTIF('09-26'!G27:AO27,"CSE/RPX")+COUNTIF('09-26'!G28:AO28,"CSE/RPX")+COUNTIF('09-26'!G10:AO10,"RPX")+COUNTIF('09-26'!G9:AO9,"RPX")+COUNTIF('09-26'!G8:AO8,"RPX")+COUNTIF('09-26'!F11:AO11,"RPX")+COUNTIF('09-26'!F12:AO12,"RPX")+COUNTIF('09-26'!G13:AO13,"RPX")+COUNTIF('09-26'!G14:AO14,"RPX")+COUNTIF('09-26'!F15:AO15,"RPX")+COUNTIF('09-26'!F16:AO16,"RPX")+COUNTIF('09-26'!F17:AO17,"RPX")+COUNTIF('09-26'!F18:AO18,"RPX")+COUNTIF('09-26'!G19:AO19,"RPX")+COUNTIF('09-26'!G20:AO20,"RPX")+COUNTIF('09-26'!F21:AO21,"RPX")+COUNTIF('09-26'!G22:AO22,"RPX")+COUNTIF('09-26'!G23:AO23,"RPX")+COUNTIF('09-26'!G24:AO24,"RPX")+COUNTIF('09-26'!G25:AO25,"RPX")+COUNTIF('09-26'!G26:AO26,"RPX")+COUNTIF('09-26'!G27:AO27,"RPX")+COUNTIF('09-26'!G28:AO28,"RPX"),COUNTIF(INDIRECT("'09-26'!G"&VLOOKUP($E$4,$AC$5:$AD$25,2,FALSE())&":AO"&VLOOKUP($E$4,$AC$5:$AD$25,2,FALSE())),"CSE")+COUNTIF(INDIRECT("'09-26'!G"&VLOOKUP($E$4,$AC$5:$AD$25,2,FALSE())&":AO"&VLOOKUP($E$4,$AC$5:$AD$25,2,FALSE())),"CSE/RPX")+COUNTIF(INDIRECT("'09-26'!G"&VLOOKUP($E$4,$AC$5:$AD$25,2,FALSE())&":AO"&VLOOKUP($E$4,$AC$5:$AD$25,2,FALSE())),"RPX")) -> 3 | L9: =IF($E$4="TOUS",COUNTIF('10-26'!G10:AO10,"CSE")+COUNTIF('10-26'!G9:AO9,"CSE")+COUNTIF('10-26'!G8:AO8,"CSE")+COUNTIF('10-26'!F11:AO11,"CSE")+COUNTIF('10-26'!F12:AO12,"CSE")+COUNTIF('10-26'!G13:AO13,"CSE")+COUNTIF('10-26'!F14:AO14,"CSE")+COUNTIF('10-26'!F15:AO15,"CSE")+COUNTIF('10-26'!F16:AO16,"CSE")+COUNTIF('10-26'!F17:AO17,"CSE")+COUNTIF('10-26'!G18:AO18,"CSE")+COUNTIF('10-26'!G19:AO19,"CSE")+COUNTIF('10-26'!F20:AO20,"CSE")+COUNTIF('10-26'!G21:AO21,"CSE")+COUNTIF('10-26'!G22:AO22,"CSE")+COUNTIF('10-26'!F23:AO23,"CSE")+COUNTIF('10-26'!G24:AO24,"CSE")+COUNTIF('10-26'!G25:AO25,"CSE")+COUNTIF('10-26'!G26:AO26,"CSE")+COUNTIF('10-26'!G27:AO27,"CSE")+COUNTIF('10-26'!G28:AO28,"CSE")+COUNTIF('10-26'!G10:AO10,"CSE/RPX")+COUNTIF('10-26'!G9:AO9,"CSE/RPX")+COUNTIF('10-26'!G8:AO8,"CSE/RPX")+COUNTIF('10-26'!F11:AO11,"CSE/RPX")+COUNTIF('10-26'!F12:AO12,"CSE/RPX")+COUNTIF('10-26'!G13:AO13,"CSE/RPX")+COUNTIF('10-26'!F14:AO14,"CSE/RPX")+COUNTIF('10-26'!F15:AO15,"CSE/RPX")+COUNTIF('10-26'!F16:AO16,"CSE/RPX")+COUNTIF('10-26'!F17:AO17,"CSE/RPX")+COUNTIF('10-26'!G18:AO18,"CSE/RPX")+COUNTIF('10-26'!G19:AO19,"CSE/RPX")+COUNTIF('10-26'!F20:AO20,"CSE/RPX")+COUNTIF('10-26'!G21:AO21,"CSE/RPX")+COUNTIF('10-26'!G22:AO22,"CSE/RPX")+COUNTIF('10-26'!F23:AO23,"CSE/RPX")+COUNTIF('10-26'!G24:AO24,"CSE/RPX")+COUNTIF('10-26'!G25:AO25,"CSE/RPX")+COUNTIF('10-26'!G26:AO26,"CSE/RPX")+COUNTIF('10-26'!G27:AO27,"CSE/RPX")+COUNTIF('10-26'!G28:AO28,"CSE/RPX")+COUNTIF('10-26'!G10:AO10,"RPX")+COUNTIF('10-26'!G9:AO9,"RPX")+COUNTIF('10-26'!G8:AO8,"RPX")+COUNTIF('10-26'!F11:AO11,"RPX")+COUNTIF('10-26'!F12:AO12,"RPX")+COUNTIF('10-26'!G13:AO13,"RPX")+COUNTIF('10-26'!F14:AO14,"RPX")+COUNTIF('10-26'!F15:AO15,"RPX")+COUNTIF('10-26'!F16:AO16,"RPX")+COUNTIF('10-26'!F17:AO17,"RPX")+COUNTIF('10-26'!G18:AO18,"RPX")+COUNTIF('10-26'!G19:AO19,"RPX")+COUNTIF('10-26'!F20:AO20,"RPX")+COUNTIF('10-26'!G21:AO21,"RPX")+COUNTIF('10-26'!G22:AO22,"RPX")+COUNTIF('10-26'!F23:AO23,"RPX")+COUNTIF('10-26'!G24:AO24,"RPX")+COUNTIF('10-26'!G25:AO25,"RPX")+COUNTIF('10-26'!G26:AO26,"RPX")+COUNTIF('10-26'!G27:AO27,"RPX")+COUNTIF('10-26'!G28:AO28,"RPX"),COUNTIF(INDIRECT("'10-26'!G"&VLOOKUP($E$4,$AC$5:$AD$25,2,FALSE())&":AO"&VLOOKUP($E$4,$AC$5:$AD$25,2,FALSE())),"CSE")+COUNTIF(INDIRECT("'10-26'!G"&VLOOKUP($E$4,$AC$5:$AD$25,2,FALSE())&":AO"&VLOOKUP($E$4,$AC$5:$AD$25,2,FALSE())),"CSE/RPX")+COUNTIF(INDIRECT("'10-26'!G"&VLOOKUP($E$4,$AC$5:$AD$25,2,FALSE())&":AO"&VLOOKUP($E$4,$AC$5:$AD$25,2,FALSE())),"RPX")) -> 2 | M9: =IF($E$4="TOUS",COUNTIF('11-26'!G10:AO10,"CSE")+COUNTIF('11-26'!G9:AO9,"CSE")+COUNTIF('11-26'!G8:AO8,"CSE")+COUNTIF('11-26'!G11:AO11,"CSE")+COUNTIF('11-26'!F12:AO12,"CSE")+COUNTIF('11-26'!G13:AO13,"CSE")+COUNTIF('11-26'!F14:AO14,"CSE")+COUNTIF('11-26'!F15:AO15,"CSE")+COUNTIF('11-26'!G16:AO16,"CSE")+COUNTIF('11-26'!G17:AO17,"CSE")+COUNTIF('11-26'!G18:AO18,"CSE")+COUNTIF('11-26'!G19:AO19,"CSE")+COUNTIF('11-26'!F20:AO20,"CSE")+COUNTIF('11-26'!F21:AO21,"CSE")+COUNTIF('11-26'!F22:AO22,"CSE")+COUNTIF('11-26'!G23:AO23,"CSE")+COUNTIF('11-26'!G24:AO24,"CSE")+COUNTIF('11-26'!G25:AO25,"CSE")+COUNTIF('11-26'!G26:AO26,"CSE")+COUNTIF('11-26'!G27:AO27,"CSE")+COUNTIF('11-26'!G28:AO28,"CSE")+COUNTIF('11-26'!G10:AO10,"CSE/RPX")+COUNTIF('11-26'!G9:AO9,"CSE/RPX")+COUNTIF('11-26'!G8:AO8,"CSE/RPX")+COUNTIF('11-26'!G11:AO11,"CSE/RPX")+COUNTIF('11-26'!F12:AO12,"CSE/RPX")+COUNTIF('11-26'!G13:AO13,"CSE/RPX")+COUNTIF('11-26'!F14:AO14,"CSE/RPX")+COUNTIF('11-26'!F15:AO15,"CSE/RPX")+COUNTIF('11-26'!G16:AO16,"CSE/RPX")+COUNTIF('11-26'!G17:AO17,"CSE/RPX")+COUNTIF('11-26'!G18:AO18,"CSE/RPX")+COUNTIF('11-26'!G19:AO19,"CSE/RPX")+COUNTIF('11-26'!F20:AO20,"CSE/RPX")+COUNTIF('11-26'!F21:AO21,"CSE/RPX")+COUNTIF('11-26'!F22:AO22,"CSE/RPX")+COUNTIF('11-26'!G23:AO23,"CSE/RPX")+COUNTIF('11-26'!G24:AO24,"CSE/RPX")+COUNTIF('11-26'!G25:AO25,"CSE/RPX")+COUNTIF('11-26'!G26:AO26,"CSE/RPX")+COUNTIF('11-26'!G27:AO27,"CSE/RPX")+COUNTIF('11-26'!G28:AO28,"CSE/RPX")+COUNTIF('11-26'!G10:AO10,"RPX")+COUNTIF('11-26'!G9:AO9,"RPX")+COUNTIF('11-26'!G8:AO8,"RPX")+COUNTIF('11-26'!G11:AO11,"RPX")+COUNTIF('11-26'!F12:AO12,"RPX")+COUNTIF('11-26'!G13:AO13,"RPX")+COUNTIF('11-26'!F14:AO14,"RPX")+COUNTIF('11-26'!F15:AO15,"RPX")+COUNTIF('11-26'!G16:AO16,"RPX")+COUNTIF('11-26'!G17:AO17,"RPX")+COUNTIF('11-26'!G18:AO18,"RPX")+COUNTIF('11-26'!G19:AO19,"RPX")+COUNTIF('11-26'!F20:AO20,"RPX")+COUNTIF('11-26'!F21:AO21,"RPX")+COUNTIF('11-26'!F22:AO22,"RPX")+COUNTIF('11-26'!G23:AO23,"RPX")+COUNTIF('11-26'!G24:AO24,"RPX")+COUNTIF('11-26'!G25:AO25,"RPX")+COUNTIF('11-26'!G26:AO26,"RPX")+COUNTIF('11-26'!G27:AO27,"RPX")+COUNTIF('11-26'!G28:AO28,"RPX"),COUNTIF(INDIRECT("'11-26'!G"&VLOOKUP($E$4,$AC$5:$AD$25,2,FALSE())&":AO"&VLOOKUP($E$4,$AC$5:$AD$25,2,FALSE())),"CSE")+COUNTIF(INDIRECT("'11-26'!G"&VLOOKUP($E$4,$AC$5:$AD$25,2,FALSE())&":AO"&VLOOKUP($E$4,$AC$5:$AD$25,2,FALSE())),"CSE/RPX")+COUNTIF(INDIRECT("'11-26'!G"&VLOOKUP($E$4,$AC$5:$AD$25,2,FALSE())&":AO"&VLOOKUP($E$4,$AC$5:$AD$25,2,FALSE())),"RPX")) -> 2 | N9: =IF($E$4="TOUS",COUNTIF('12-26'!G10:AO10,"CSE")+COUNTIF('12-26'!G9:AO9,"CSE")+COUNTIF('12-26'!G8:AO8,"CSE")+COUNTIF('12-26'!G11:AO11,"CSE")+COUNTIF('12-26'!G12:AO12,"CSE")+COUNTIF('12-26'!G13:AO13,"CSE")+COUNTIF('12-26'!G14:AO14,"CSE")+COUNTIF('12-26'!F15:AO15,"CSE")+COUNTIF('12-26'!G16:AO16,"CSE")+COUNTIF('12-26'!F17:AO17,"CSE")+COUNTIF('12-26'!G18:AO18,"CSE")+COUNTIF('12-26'!G19:AO19,"CSE")+COUNTIF('12-26'!F20:AO20,"CSE")+COUNTIF('12-26'!F21:AO21,"CSE")+COUNTIF('12-26'!F22:AO22,"CSE")+COUNTIF('12-26'!G23:AO23,"CSE")+COUNTIF('12-26'!G24:AO24,"CSE")+COUNTIF('12-26'!G25:AO25,"CSE")+COUNTIF('12-26'!G26:AO26,"CSE")+COUNTIF('12-26'!G27:AO27,"CSE")+COUNTIF('12-26'!G28:AO28,"CSE")+COUNTIF('12-26'!G10:AO10,"CSE/RPX")+COUNTIF('12-26'!G9:AO9,"CSE/RPX")+COUNTIF('12-26'!G8:AO8,"CSE/RPX")+COUNTIF('12-26'!G11:AO11,"CSE/RPX")+COUNTIF('12-26'!G12:AO12,"CSE/RPX")+COUNTIF('12-26'!G13:AO13,"CSE/RPX")+COUNTIF('12-26'!G14:AO14,"CSE/RPX")+COUNTIF('12-26'!F15:AO15,"CSE/RPX")+COUNTIF('12-26'!G16:AO16,"CSE/RPX")+COUNTIF('12-26'!F17:AO17,"CSE/RPX")+COUNTIF('12-26'!G18:AO18,"CSE/RPX")+COUNTIF('12-26'!G19:AO19,"CSE/RPX")+COUNTIF('12-26'!F20:AO20,"CSE/RPX")+COUNTIF('12-26'!F21:AO21,"CSE/RPX")+COUNTIF('12-26'!F22:AO22,"CSE/RPX")+COUNTIF('12-26'!G23:AO23,"CSE/RPX")+COUNTIF('12-26'!G24:AO24,"CSE/RPX")+COUNTIF('12-26'!G25:AO25,"CSE/RPX")+COUNTIF('12-26'!G26:AO26,"CSE/RPX")+COUNTIF('12-26'!G27:AO27,"CSE/RPX")+COUNTIF('12-26'!G28:AO28,"CSE/RPX")+COUNTIF('12-26'!G10:AO10,"RPX")+COUNTIF('12-26'!G9:AO9,"RPX")+COUNTIF('12-26'!G8:AO8,"RPX")+COUNTIF('12-26'!G11:AO11,"RPX")+COUNTIF('12-26'!G12:AO12,"RPX")+COUNTIF('12-26'!G13:AO13,"RPX")+COUNTIF('12-26'!G14:AO14,"RPX")+COUNTIF('12-26'!F15:AO15,"RPX")+COUNTIF('12-26'!G16:AO16,"RPX")+COUNTIF('12-26'!F17:AO17,"RPX")+COUNTIF('12-26'!G18:AO18,"RPX")+COUNTIF('12-26'!G19:AO19,"RPX")+COUNTIF('12-26'!F20:AO20,"RPX")+COUNTIF('12-26'!F21:AO21,"RPX")+COUNTIF('12-26'!F22:AO22,"RPX")+COUNTIF('12-26'!G23:AO23,"RPX")+COUNTIF('12-26'!G24:AO24,"RPX")+COUNTIF('12-26'!G25:AO25,"RPX")+COUNTIF('12-26'!G26:AO26,"RPX")+COUNTIF('12-26'!G27:AO27,"RPX")+COUNTIF('12-26'!G28:AO28,"RPX"),COUNTIF(INDIRECT("'12-26'!G"&VLOOKUP($E$4,$AC$5:$AD$25,2,FALSE())&":AO"&VLOOKUP($E$4,$AC$5:$AD$25,2,FALSE())),"CSE")+COUNTIF(INDIRECT("'12-26'!G"&VLOOKUP($E$4,$AC$5:$AD$25,2,FALSE())&":AO"&VLOOKUP($E$4,$AC$5:$AD$25,2,FALSE())),"CSE/RPX")+COUNTIF(INDIRECT("'12-26'!G"&VLOOKUP($E$4,$AC$5:$AD$25,2,FALSE())&":AO"&VLOOKUP($E$4,$AC$5:$AD$25,2,FALSE())),"RPX")) -> 0 | O9: =SUM(C9:N9) -> 39 | Q9: MAJET P. | R9: =COUNTIF('01-26'!G9:AO9,"TP")+COUNTIF('02-26'!G9:AO9,"TP")+COUNTIF('03-26'!G9:AO9,"TP")+COUNTIF('04-26'!G9:AO9,"TP")+COUNTIF('05-26'!G9:AO9,"TP")+COUNTIF('06-26'!G9:AO9,"TP")+COUNTIF('07-26'!G9:AO9,"TP")+COUNTIF('08-26'!G9:AO9,"TP")+COUNTIF('09-26'!G9:AO9,"TP")+COUNTIF('10-26'!G9:AO9,"TP")+COUNTIF('11-26'!G9:AO9,"TP")+COUNTIF('12-26'!G9:AO9,"TP") -> 0 | S9: =COUNTIF('01-26'!G9:AO9,"CSE")+COUNTIF('01-26'!G9:AO9,"CSE/RPX")+COUNTIF('01-26'!G9:AO9,"RPX")+COUNTIF('02-26'!G9:AO9,"CSE")+COUNTIF('02-26'!G9:AO9,"CSE/RPX")+COUNTIF('02-26'!G9:AO9,"RPX")+COUNTIF('03-26'!G9:AO9,"CSE")+COUNTIF('03-26'!G9:AO9,"CSE/RPX")+COUNTIF('03-26'!G9:AO9,"RPX")+COUNTIF('04-26'!G9:AO9,"CSE")+COUNTIF('04-26'!G9:AO9,"CSE/RPX")+COUNTIF('04-26'!G9:AO9,"RPX")+COUNTIF('05-26'!G9:AO9,"CSE")+COUNTIF('05-26'!G9:AO9,"CSE/RPX")+COUNTIF('05-26'!G9:AO9,"RPX")+COUNTIF('06-26'!G9:AO9,"CSE")+COUNTIF('06-26'!G9:AO9,"CSE/RPX")+COUNTIF('06-26'!G9:AO9,"RPX")+COUNTIF('07-26'!G9:AO9,"CSE")+COUNTIF('07-26'!G9:AO9,"CSE/RPX")+COUNTIF('07-26'!G9:AO9,"RPX")+COUNTIF('08-26'!G9:AO9,"CSE")+COUNTIF('08-26'!G9:AO9,"CSE/RPX")+COUNTIF('08-26'!G9:AO9,"RPX")+COUNTIF('09-26'!G9:AO9,"CSE")+COUNTIF('09-26'!G9:AO9,"CSE/RPX")+COUNTIF('09-26'!G9:AO9,"RPX")+COUNTIF('10-26'!G9:AO9,"CSE")+COUNTIF('10-26'!G9:AO9,"CSE/RPX")+COUNTIF('10-26'!G9:AO9,"RPX")+COUNTIF('11-26'!G9:AO9,"CSE")+COUNTIF('11-26'!G9:AO9,"CSE/RPX")+COUNTIF('11-26'!G9:AO9,"RPX")+COUNTIF('12-26'!G9:AO9,"CSE")+COUNTIF('12-26'!G9:AO9,"CSE/RPX")+COUNTIF('12-26'!G9:AO9,"RPX") -> 0 | T9: =COUNTIF('01-26'!G9:AO9,"CA/RC")+COUNTIF('01-26'!G9:AO9,"CA")+COUNTIF('02-26'!G9:AO9,"CA/RC")+COUNTIF('02-26'!G9:AO9,"CA")+COUNTIF('03-26'!G9:AO9,"CA/RC")+COUNTIF('03-26'!G9:AO9,"CA")+COUNTIF('04-26'!G9:AO9,"CA/RC")+COUNTIF('04-26'!G9:AO9,"CA")+COUNTIF('05-26'!G9:AO9,"CA/RC")+COUNTIF('05-26'!G9:AO9,"CA")+COUNTIF('06-26'!G9:AO9,"CA/RC")+COUNTIF('06-26'!G9:AO9,"CA")+COUNTIF('07-26'!G9:AO9,"CA/RC")+COUNTIF('07-26'!G9:AO9,"CA")+COUNTIF('08-26'!G9:AO9,"CA/RC")+COUNTIF('08-26'!G9:AO9,"CA")+COUNTIF('09-26'!G9:AO9,"CA/RC")+COUNTIF('09-26'!G9:AO9,"CA")+COUNTIF('10-26'!G9:AO9,"CA/RC")+COUNTIF('10-26'!G9:AO9,"CA")+COUNTIF('11-26'!G9:AO9,"CA/RC")+COUNTIF('11-26'!G9:AO9,"CA")+COUNTIF('12-26'!G9:AO9,"CA/RC")+COUNTIF('12-26'!G9:AO9,"CA") -> 34 | U9: =COUNTIF('01-26'!G9:AO9,"ATM/ATA")+COUNTIF('01-26'!G9:AO9,"ATM")+COUNTIF('01-26'!G9:AO9,"ATA")+COUNTIF('02-26'!G9:AO9,"ATM/ATA")+COUNTIF('02-26'!G9:AO9,"ATM")+COUNTIF('02-26'!G9:AO9,"ATA")+COUNTIF('03-26'!G9:AO9,"ATM/ATA")+COUNTIF('03-26'!G9:AO9,"ATM")+COUNTIF('03-26'!G9:AO9,"ATA")+COUNTIF('04-26'!G9:AO9,"ATM/ATA")+COUNTIF('04-26'!G9:AO9,"ATM")+COUNTIF('04-26'!G9:AO9,"ATA")+COUNTIF('05-26'!G9:AO9,"ATM/ATA")+COUNTIF('05-26'!G9:AO9,"ATM")+COUNTIF('05-26'!G9:AO9,"ATA")+COUNTIF('06-26'!G9:AO9,"ATM/ATA")+COUNTIF('06-26'!G9:AO9,"ATM")+COUNTIF('06-26'!G9:AO9,"ATA")+COUNTIF('07-26'!G9:AO9,"ATM/ATA")+COUNTIF('07-26'!G9:AO9,"ATM")+COUNTIF('07-26'!G9:AO9,"ATA")+COUNTIF('08-26'!G9:AO9,"ATM/ATA")+COUNTIF('08-26'!G9:AO9,"ATM")+COUNTIF('08-26'!G9:AO9,"ATA")+COUNTIF('09-26'!G9:AO9,"ATM/ATA")+COUNTIF('09-26'!G9:AO9,"ATM")+COUNTIF('09-26'!G9:AO9,"ATA")+COUNTIF('10-26'!G9:AO9,"ATM/ATA")+COUNTIF('10-26'!G9:AO9,"ATM")+COUNTIF('10-26'!G9:AO9,"ATA")+COUNTIF('11-26'!G9:AO9,"ATM/ATA")+COUNTIF('11-26'!G9:AO9,"ATM")+COUNTIF('11-26'!G9:AO9,"ATA")+COUNTIF('12-26'!G9:AO9,"ATM/ATA")+COUNTIF('12-26'!G9:AO9,"ATM")+COUNTIF('12-26'!G9:AO9,"ATA") -> 0 | V9: =COUNTIF('01-26'!G9:AO9,"ASA")+COUNTIF('02-26'!G9:AO9,"ASA")+COUNTIF('03-26'!G9:AO9,"ASA")+COUNTIF('04-26'!G9:AO9,"ASA")+COUNTIF('05-26'!G9:AO9,"ASA")+COUNTIF('06-26'!G9:AO9,"ASA")+COUNTIF('07-26'!G9:AO9,"ASA")+COUNTIF('08-26'!G9:AO9,"ASA")+COUNTIF('09-26'!G9:AO9,"ASA")+COUNTIF('10-26'!G9:AO9,"ASA")+COUNTIF('11-26'!G9:AO9,"ASA")+COUNTIF('12-26'!G9:AO9,"ASA") -> 0 | W9: =COUNTIF('01-26'!G9:AO9,"FORM")+COUNTIF('02-26'!G9:AO9,"FORM")+COUNTIF('03-26'!G9:AO9,"FORM")+COUNTIF('04-26'!G9:AO9,"FORM")+COUNTIF('05-26'!G9:AO9,"FORM")+COUNTIF('06-26'!G9:AO9,"FORM")+COUNTIF('07-26'!G9:AO9,"FORM")+COUNTIF('08-26'!G9:AO9,"FORM")+COUNTIF('09-26'!G9:AO9,"FORM")+COUNTIF('10-26'!G9:AO9,"FORM")+COUNTIF('11-26'!G9:AO9,"FORM")+COUNTIF('12-26'!G9:AO9,"FORM") -> 0 | X9: =COUNTIF('01-26'!G9:AO9,"RPM")+COUNTIF('01-26'!G9:AO9,"JPS")+COUNTIF('02-26'!G9:AO9,"RPM")+COUNTIF('02-26'!G9:AO9,"JPS")+COUNTIF('03-26'!G9:AO9,"RPM")+COUNTIF('03-26'!G9:AO9,"JPS")+COUNTIF('04-26'!G9:AO9,"RPM")+COUNTIF('04-26'!G9:AO9,"JPS")+COUNTIF('05-26'!G9:AO9,"RPM")+COUNTIF('05-26'!G9:AO9,"JPS")+COUNTIF('06-26'!G9:AO9,"RPM")+COUNTIF('06-26'!G9:AO9,"JPS")+COUNTIF('07-26'!G9:AO9,"RPM")+COUNTIF('07-26'!G9:AO9,"JPS")+COUNTIF('08-26'!G9:AO9,"RPM")+COUNTIF('08-26'!G9:AO9,"JPS")+COUNTIF('09-26'!G9:AO9,"RPM")+COUNTIF('09-26'!G9:AO9,"JPS")+COUNTIF('10-26'!G9:AO9,"RPM")+COUNTIF('10-26'!G9:AO9,"JPS")+COUNTIF('11-26'!G9:AO9,"RPM")+COUNTIF('11-26'!G9:AO9,"JPS")+COUNTIF('12-26'!G9:AO9,"RPM")+COUNTIF('12-26'!G9:AO9,"JPS") -> 0 | Y9: =SUM(R9:X9) -> 34 | AB9: BAUDET R. | AC9: LALANNE P. | AD9: 12
